<?xml version="1.0"?>
<robot xmlns:xacro="http://www.ros.org/wiki/xacro">
   <xacro:include filename="$(find fishbot)/urdf/common_inertia.xacro" />

    <xacro:macro name="wheel_xacro" params="wheel_name length radius xyz">  <!-- 定义宏，用wheel和xyz两个参数的地方等下可以被参数替换 -->
        <link name="${wheel_name}_wheel_link">
            <visual>
                <origin xyz="0 0 0" rpy="1.57079 0 0" />   <!-- 这个轮子默认是横着的，绕x轴选择90度竖起来 -->
                <geometry>
                    <cylinder length="${length}" radius="${radius}" />
                </geometry>
                <material name="black">
                    <color rgba="0.0 0.0 0.0 0.8"/>
                </material>
            </visual>
            <collision>
                <origin xyz="0 0 0" rpy="1.57079 0 0" />
                <geometry>
                    <cylinder length="${length}" radius="${radius}" />
                </geometry>
                <material name="black">
                    <color rgba="0.0 0.0 0.0 0.8"/>
                </material>
            </collision>

            <xacro:cylinder_inertia m="0.1" h="${length}" r="${radius}"/>
        </link>

        <gazebo reference="${wheel_name}_wheel_link">
            <mu1 value="20.0" />                  <!-- 切向的摩擦系数 -->
            <mu2 value="20.0" />                  <!-- 法向的摩擦系数 -->
            <kp value="1000000.0" />           <!-- 接触的刚度系数 -->
            <kd value="1.0" />                    <!-- 阻尼系数 -->
        </gazebo>

        <joint name="${wheel_name}_wheel_joint" type="continuous">
            <parent link="base_link" />
            <child link="${wheel_name}_wheel_link" />
            <origin xyz="${xyz}" />
            <axis xyz="0 1 0" />  <!-- 表示这个轮子绕着y轴转 -->
        </joint>
    </xacro:macro>
</robot>
